<mujoco model="go1">
  <compiler angle="radian" meshdir="../meshes/" autolimits="true" />
  <option cone="elliptic" impratio="100" />
  <default>
    <default class="go1">
      <geom friction="0.6" margin="0.001" condim="1" />
      <joint axis="0 1 0" damping="0.1" armature="0.01" frictionloss="0.2" />
      <motor ctrlrange="-23.7 23.7" ctrllimited="true" />
      <default class="abduction">
        <joint axis="1 0 0" range="-0.863 0.863" />
      </default>
      <default class="hip">
        <joint range="-0.686 4.501" />
      </default>
      <default class="knee">
        <joint range="-2.818 -0.888" />
        <motor ctrlrange="-35.55 35.55" />
      </default>
      <default class="visual">
        <geom type="mesh" contype="0" conaffinity="0" group="2" material="dark" />
      </default>
      <default class="collision">
        <geom group="3" type="capsule" />
        <default class="hip_left1">
          <geom size="0.046 0.02" pos="0 0.045 0" quat="1 1 0 0" type="cylinder" />
        </default>
        <default class="hip_left2">
          <geom size="0.031 0.02" pos="0 0.065 0" quat="1 1 0 0" type="cylinder" />
        </default>
        <default class="hip_left3">
          <geom size="0.046 0.02" quat="1 1 0 0" type="cylinder" />
        </default>
        <default class="hip_right1">
          <geom size="0.046 0.02" pos="0 -0.045 0" quat="1 1 0 0" type="cylinder" />
        </default>
        <default class="hip_right2">
          <geom size="0.031 0.02" pos="0 -0.065 0" quat="1 1 0 0" type="cylinder" />
        </default>
        <default class="hip_right3">
          <geom size="0.046 0.02" quat="1 1 0 0" type="cylinder" />
        </default>
        <default class="thigh1">
          <geom size="0.015" fromto="-0.02 0 0 -0.02 0 -0.16" />
        </default>
        <default class="thigh2">
          <geom size="0.015" fromto="0 0 0 -0.02 0 -0.1" />
        </default>
        <default class="thigh3">
          <geom size="0.015" fromto="-0.02 0 -0.16 0 0 -0.2" />
        </default>
        <default class="calf1">
          <geom size="0.01" fromto="0 0 0 0.02 0 -0.13" />
        </default>
        <default class="calf2">
          <geom size="0.01" fromto="0.02 0 -0.13 0 0 -0.2" />
        </default>
        <default class="foot">
          <geom type="sphere" size="0.023" pos="0 0 -0.213" priority="1" solimp="0.015 1 0.023" condim="6" friction="0.8 0.02 0.01" />
        </default>
      </default>
    </default>
  </default>
  <asset>
    <material name="dark" rgba="0.2 0.2 0.2 1" />
    <mesh class="go1" file="trunk.stl" />
    <mesh class="go1" file="hip.stl" />
    <mesh class="go1" file="thigh_mirror.stl" />
    <mesh class="go1" file="calf.stl" />
    <mesh class="go1" file="thigh.stl" />
    <texture type="skybox" builtin="gradient" rgb1="0.3 0.5 0.7" rgb2="0 0 0" width="512" height="3072" />
    <texture type="2d" name="groundplane" builtin="checker" mark="edge" rgb1="0.2 0.3 0.4" rgb2="0.1 0.2 0.3" markrgb="0.8 0.8 0.8" width="300" height="300" />
    <material name="groundplane" texture="groundplane" texuniform="true" texrepeat="5 5" reflectance="0.2" />
  </asset>
  <visual>
    <headlight diffuse="0.6 0.6 0.6" ambient="0.3 0.3 0.3" specular="0 0 0" />
    <rgba haze="0.15 0.25 0.35 1" />
    <global azimuth="120" elevation="-20" />
  </visual>
  <worldbody>
    <light pos="0 0 1.5" dir="0 0 -1" directional="true" />
    <geom name="floor" size="0 0 0.05" type="plane" material="groundplane" />
    <body name="trunk" pos="0 0 0.32" childclass="go1">
      <camera name="tracking" mode="trackcom" pos="0 -1 0.8" xyaxes="1 0 0 0 1 1" />
      <inertial pos="0.0223 0.002 -0.0005" quat="0.999990548782 0.00234348184302 -0.0026811332993 0.00249438655944" mass="5.29" diaginertia="0.0168101299449 0.0630105180079 0.0716565002472" />
      <freejoint />
      <geom class="visual" mesh="trunk" />
      <geom class="collision" size="0.125 0.04 0.057" type="box" />
      <geom class="collision" quat="1 0 1 0" pos="0 -0.04 0" size="0.058 0.125" type="cylinder" />
      <geom class="collision" quat="1 0 1 0" pos="0 +0.04 0" size="0.058 0.125" type="cylinder" />
      <site name="imu" pos="0 0 0" />
      <body name="FR_hip" pos="0.1881 -0.04675 0">
        <inertial pos="-0.005657 0.008752 -0.000102" quat="0.709375787428 0.70450199718 -0.00623068232027 -0.0205938529091" mass="0.591" diaginertia="0.00033357060263 0.000400591834184 0.000619523321186" />
        <joint class="abduction" name="FR_hip_joint" />
        <geom class="visual" mesh="hip" quat="1 0 0 0" />
        <geom class="hip_right1" />
        <geom class="hip_right2" />
        <body name="FR_thigh" pos="0 -0.08 0">
          <inertial pos="-0.003342 0.018054 -0.033451" quat="0.558949969368 0.397495263089 0.524074081887 -0.504894844754" mass="0.92" diaginertia="0.000641595244732 0.0044404464491 0.00457569999317" />
          <joint class="hip" name="FR_thigh_joint" />
          <geom class="visual" mesh="thigh_mirror" />
          <geom class="thigh1" />
          <geom class="thigh2" />
          <geom class="thigh3" />
          <body name="FR_calf" pos="0 0 -0.213">
            <inertial pos="0.006197 0.001408 -0.116695" quat="0.50639420374 0.496900109666 0.50397088238 -0.492613987971" mass="0.135862" diaginertia="2.47358147004e-05 0.00108883563189 0.00110043780641" />
            <joint class="knee" name="FR_calf_joint" />
            <geom class="visual" mesh="calf" />
            <geom class="calf1" />
            <geom class="calf2" />
            <geom name="FR" class="foot" />
          </body>
        </body>
      </body>
      <body name="FL_hip" pos="0.1881 0.04675 0">
        <inertial pos="-0.005657 -0.008752 -0.000102" quat="0.709375787428 -0.70450199718 -0.00623068232027 0.0205938529091" mass="0.591" diaginertia="0.00033357060263 0.000400591834184 0.000619523321186" />
        <joint class="abduction" name="FL_hip_joint" />
        <geom class="visual" mesh="hip" />
        <geom class="hip_left1" />
        <geom class="hip_left2" />
        <body name="FL_thigh" pos="0 0.08 0">
          <inertial pos="-0.003342 -0.018054 -0.033451" quat="0.397495263089 0.558949969368 0.504894844754 -0.524074081887" mass="0.92" diaginertia="0.000641595244732 0.0044404464491 0.00457569999317" />
          <joint class="hip" name="FL_thigh_joint" />
          <geom class="visual" mesh="thigh" />
          <geom class="thigh1" />
          <geom class="thigh2" />
          <geom class="thigh3" />
          <body name="FL_calf" pos="0 0 -0.213">
            <inertial pos="0.006197 0.001408 -0.116695" quat="0.50639420374 0.496900109666 0.50397088238 -0.492613987971" mass="0.135862" diaginertia="2.47358147004e-05 0.00108883563189 0.00110043780641" />
            <joint class="knee" name="FL_calf_joint" />
            <geom class="visual" mesh="calf" />
            <geom class="calf1" />
            <geom class="calf2" />
            <geom name="FL" class="foot" />
          </body>
        </body>
      </body>
      <body name="RR_hip" pos="-0.1881 -0.04675 0">
        <inertial pos="0.005657 0.008752 -0.000102" quat="0.709375787428 0.70450199718 0.00623068232027 0.0205938529091" mass="0.591" diaginertia="0.00033357060263 0.000400591834184 0.000619523321186" />
        <joint class="abduction" name="RR_hip_joint" />
        <geom class="visual" quat="0 0 0 -1" mesh="hip" />
        <geom class="hip_right1" />
        <geom class="hip_right2" />
        <geom class="hip_right3" />
        <body name="RR_thigh" pos="0 -0.08 0">
          <inertial pos="-0.003342 0.018054 -0.033451" quat="0.558949969368 0.397495263089 0.524074081887 -0.504894844754" mass="0.92" diaginertia="0.000641595244732 0.0044404464491 0.00457569999317" />
          <joint class="hip" name="RR_thigh_joint" />
          <geom class="visual" mesh="thigh_mirror" />
          <geom class="thigh1" />
          <geom class="thigh2" />
          <geom class="thigh3" />
          <body name="RR_calf" pos="0 0 -0.213">
            <inertial pos="0.006197 0.001408 -0.116695" quat="0.50639420374 0.496900109666 0.50397088238 -0.492613987971" mass="0.135862" diaginertia="2.47358147004e-05 0.00108883563189 0.00110043780641" />
            <joint class="knee" name="RR_calf_joint" />
            <geom class="visual" mesh="calf" />
            <geom class="calf1" />
            <geom class="calf2" />
            <geom name="RR" class="foot" />
          </body>
        </body>
      </body>
      <body name="RL_hip" pos="-0.1881 0.04675 0">
        <inertial pos="0.005657 -0.008752 -0.000102" quat="0.709375787428 -0.70450199718 0.00623068232027 -0.0205938529091" mass="0.591" diaginertia="0.00033357060263 0.000400591834184 0.000619523321186" />
        <joint class="abduction" name="RL_hip_joint" />
        <geom class="visual" quat="0 0 1 0" mesh="hip" />
        <geom class="hip_left1" />
        <geom class="hip_left2" />
        <geom class="hip_left3" />
        <body name="RL_thigh" pos="0 0.08 0">
          <inertial pos="-0.003342 -0.018054 -0.033451" quat="0.397495263089 0.558949969368 0.504894844754 -0.524074081887" mass="0.92" diaginertia="0.000641595244732 0.0044404464491 0.00457569999317" />
          <joint class="hip" name="RL_thigh_joint" />
          <geom class="visual" mesh="thigh" />
          <geom class="thigh1" />
          <geom class="thigh2" />
          <geom class="thigh3" />
          <body name="RL_calf" pos="0 0 -0.213">
            <inertial pos="0.006197 0.001408 -0.116695" quat="0.50639420374 0.496900109666 0.50397088238 -0.492613987971" mass="0.135862" diaginertia="2.47358147004e-05 0.00108883563189 0.00110043780641" />
            <joint class="knee" name="RL_calf_joint" />
            <geom class="visual" mesh="calf" />
            <geom class="calf1" />
            <geom class="calf2" />
            <geom name="RL" class="foot" />
          </body>
        </body>
      </body>
    </body>
  </worldbody>
  <actuator>
    <motor class="abduction" name="FR_hip" joint="FR_hip_joint" />
    <motor class="hip" name="FR_thigh" joint="FR_thigh_joint" />
    <motor class="knee" name="FR_calf" joint="FR_calf_joint" />
    <motor class="abduction" name="FL_hip" joint="FL_hip_joint" />
    <motor class="hip" name="FL_thigh" joint="FL_thigh_joint" />
    <motor class="knee" name="FL_calf" joint="FL_calf_joint" />
    <motor class="abduction" name="RR_hip" joint="RR_hip_joint" />
    <motor class="hip" name="RR_thigh" joint="RR_thigh_joint" />
    <motor class="knee" name="RR_calf" joint="RR_calf_joint" />
    <motor class="abduction" name="RL_hip" joint="RL_hip_joint" />
    <motor class="hip" name="RL_thigh" joint="RL_thigh_joint" />
    <motor class="knee" name="RL_calf" joint="RL_calf_joint" />
  </actuator>
  <sensor>
    <jointpos name="FR_hip_pos" joint="FR_hip_joint" />
    <jointpos name="FR_thigh_pos" joint="FR_thigh_joint" />
    <jointpos name="FR_calf_pos" joint="FR_calf_joint" />
    <jointpos name="FL_hip_pos" joint="FL_hip_joint" />
    <jointpos name="FL_thigh_pos" joint="FL_thigh_joint" />
    <jointpos name="FL_calf_pos" joint="FL_calf_joint" />
    <jointpos name="RR_hip_pos" joint="RR_hip_joint" />
    <jointpos name="RR_thigh_pos" joint="RR_thigh_joint" />
    <jointpos name="RR_calf_pos" joint="RR_calf_joint" />
    <jointpos name="RL_hip_pos" joint="RL_hip_joint" />
    <jointpos name="RL_thigh_pos" joint="RL_thigh_joint" />
    <jointpos name="RL_calf_pos" joint="RL_calf_joint" />
    <jointvel name="FR_hip_vel" joint="FR_hip_joint" />
    <jointvel name="FR_thigh_vel" joint="FR_thigh_joint" />
    <jointvel name="FR_calf_vel" joint="FR_calf_joint" />
    <jointvel name="FL_hip_vel" joint="FL_hip_joint" />
    <jointvel name="FL_thigh_vel" joint="FL_thigh_joint" />
    <jointvel name="FL_calf_vel" joint="FL_calf_joint" />
    <jointvel name="RR_hip_vel" joint="RR_hip_joint" />
    <jointvel name="RR_thigh_vel" joint="RR_thigh_joint" />
    <jointvel name="RR_calf_vel" joint="RR_calf_joint" />
    <jointvel name="RL_hip_vel" joint="RL_hip_joint" />
    <jointvel name="RL_thigh_vel" joint="RL_thigh_joint" />
    <jointvel name="RL_calf_vel" joint="RL_calf_joint" />
    <accelerometer name="Body_Acc" site="imu" />
    <gyro name="Body_Gyro" site="imu" />
    <framequat name="Body_Quat" objtype="site" objname="imu" />
    <framepos name="Body_Pos" objtype="site" objname="imu" />
  </sensor>
  <keyframe>
    <key name="home" qpos="0 0 0.32 1 0 0 0 0 0.72 -1.44 0 0.72 -1.44 0 0.72 -1.44 0 0.72 -1.44" />
  </keyframe>
</mujoco>